[03/Mar/2023 11:19:20] DEBUG [asyncio:623] Using proactor: IocpProactor
[03/Mar/2023 11:19:34] DEBUG [asyncio:623] Using proactor: IocpProactor
[03/Mar/2023 11:19:42] DEBUG [asyncio:623] Using proactor: IocpProactor
[03/Mar/2023 11:19:56] WARNING [django.request:224] Not Found: /favicon.ico
[03/Mar/2023 11:19:56] WARNING [django.server:161] "GET /favicon.ico HTTP/1.1" 404 2116
[03/Mar/2023 11:19:58] DEBUG [asyncio:623] Using proactor: IocpProactor
[03/Mar/2023 11:19:59] DEBUG [asyncio:623] Using proactor: IocpProactor
[03/Mar/2023 11:20:12] DEBUG [asyncio:623] Using proactor: IocpProactor
[03/Mar/2023 11:21:35] DEBUG [asyncio:623] Using proactor: IocpProactor
[03/Mar/2023 13:18:47] DEBUG [asyncio:623] Using proactor: IocpProactor
[03/Mar/2023 13:20:15] DEBUG [asyncio:623] Using proactor: IocpProactor
[03/Mar/2023 13:20:37] DEBUG [asyncio:623] Using proactor: IocpProactor
[03/Mar/2023 13:21:10] DEBUG [asyncio:623] Using proactor: IocpProactor
[03/Mar/2023 13:21:21] DEBUG [asyncio:623] Using proactor: IocpProactor
[03/Mar/2023 13:21:29] DEBUG [asyncio:623] Using proactor: IocpProactor
[03/Mar/2023 13:21:44] DEBUG [asyncio:623] Using proactor: IocpProactor
[03/Mar/2023 13:21:54] DEBUG [asyncio:623] Using proactor: IocpProactor
[03/Mar/2023 13:21:59] DEBUG [asyncio:623] Using proactor: IocpProactor
[03/Mar/2023 13:22:04] DEBUG [asyncio:623] Using proactor: IocpProactor
[03/Mar/2023 13:22:48] DEBUG [asyncio:623] Using proactor: IocpProactor
[03/Mar/2023 13:22:58] DEBUG [asyncio:623] Using proactor: IocpProactor
[03/Mar/2023 23:35:28] DEBUG [asyncio:623] Using proactor: IocpProactor
[03/Mar/2023 23:35:28] DEBUG [asyncio:623] Using proactor: IocpProactor
[03/Mar/2023 23:36:26] DEBUG [asyncio:623] Using proactor: IocpProactor
[03/Mar/2023 23:36:26] DEBUG [asyncio:623] Using proactor: IocpProactor
[03/Mar/2023 23:37:04] DEBUG [asyncio:623] Using proactor: IocpProactor
[03/Mar/2023 23:37:04] DEBUG [asyncio:623] Using proactor: IocpProactor
[03/Mar/2023 23:40:19] DEBUG [oauthlib.oauth2.rfc6749.endpoints.resource:70] Dispatching token_type Bearer request to <oauthlib.oauth2.rfc6749.tokens.BearerToken object at 0x000002DF31D8FC70>.
[03/Mar/2023 23:40:54] DEBUG [oauthlib.oauth2.rfc6749.endpoints.resource:70] Dispatching token_type Bearer request to <oauthlib.oauth2.rfc6749.tokens.BearerToken object at 0x000002DF31A6DE00>.
[03/Mar/2023 23:41:24] DEBUG [oauthlib.oauth2.rfc6749.endpoints.resource:70] Dispatching token_type Bearer request to <oauthlib.oauth2.rfc6749.tokens.BearerToken object at 0x000002DF31B29A40>.
[03/Mar/2023 23:47:31] DEBUG [oauthlib.oauth2.rfc6749.endpoints.resource:70] Dispatching token_type Bearer request to <oauthlib.oauth2.rfc6749.tokens.BearerToken object at 0x000002DF31B29CC0>.
[03/Mar/2023 23:47:31] ERROR [django.request:224] Internal Server Error: /property_owner/room_options/
Traceback (most recent call last):
  File "C:\Users\DigitalHouse\AppData\Local\Programs\Python\Python39\lib\site-packages\django\core\handlers\exception.py", line 47, in inner
    response = get_response(request)
  File "C:\Users\DigitalHouse\AppData\Local\Programs\Python\Python39\lib\site-packages\django\core\handlers\base.py", line 204, in _get_response
    response = response.render()
  File "C:\Users\DigitalHouse\AppData\Local\Programs\Python\Python39\lib\site-packages\django\template\response.py", line 105, in render
    self.content = self.rendered_content
  File "C:\Users\DigitalHouse\AppData\Local\Programs\Python\Python39\lib\site-packages\rest_framework\response.py", line 70, in rendered_content
    ret = renderer.render(self.data, accepted_media_type, context)
  File "C:\Users\DigitalHouse\AppData\Local\Programs\Python\Python39\lib\site-packages\rest_framework\renderers.py", line 100, in render
    ret = json.dumps(
  File "C:\Users\DigitalHouse\AppData\Local\Programs\Python\Python39\lib\site-packages\rest_framework\utils\json.py", line 25, in dumps
    return json.dumps(*args, **kwargs)
  File "C:\Users\DigitalHouse\AppData\Local\Programs\Python\Python39\lib\json\__init__.py", line 234, in dumps
    return cls(
  File "C:\Users\DigitalHouse\AppData\Local\Programs\Python\Python39\lib\json\encoder.py", line 199, in encode
    chunks = self.iterencode(o, _one_shot=True)
  File "C:\Users\DigitalHouse\AppData\Local\Programs\Python\Python39\lib\json\encoder.py", line 257, in iterencode
    return _iterencode(o, 0)
  File "C:\Users\DigitalHouse\AppData\Local\Programs\Python\Python39\lib\site-packages\rest_framework\utils\encoders.py", line 67, in default
    return super().default(obj)
  File "C:\Users\DigitalHouse\AppData\Local\Programs\Python\Python39\lib\json\encoder.py", line 179, in default
    raise TypeError(f'Object of type {o.__class__.__name__} '
TypeError: Object of type IntegerField is not JSON serializable
[03/Mar/2023 23:47:31] ERROR [django.server:161] "POST /property_owner/room_options/ HTTP/1.1" 500 109622
[03/Mar/2023 23:48:18] DEBUG [oauthlib.oauth2.rfc6749.endpoints.resource:70] Dispatching token_type Bearer request to <oauthlib.oauth2.rfc6749.tokens.BearerToken object at 0x000002DF31DF40E0>.
[03/Mar/2023 23:48:19] ERROR [django.request:224] Internal Server Error: /property_owner/room_options/
Traceback (most recent call last):
  File "C:\Users\DigitalHouse\AppData\Local\Programs\Python\Python39\lib\site-packages\django\core\handlers\exception.py", line 47, in inner
    response = get_response(request)
  File "C:\Users\DigitalHouse\AppData\Local\Programs\Python\Python39\lib\site-packages\django\core\handlers\base.py", line 204, in _get_response
    response = response.render()
  File "C:\Users\DigitalHouse\AppData\Local\Programs\Python\Python39\lib\site-packages\django\template\response.py", line 105, in render
    self.content = self.rendered_content
  File "C:\Users\DigitalHouse\AppData\Local\Programs\Python\Python39\lib\site-packages\rest_framework\response.py", line 70, in rendered_content
    ret = renderer.render(self.data, accepted_media_type, context)
  File "C:\Users\DigitalHouse\AppData\Local\Programs\Python\Python39\lib\site-packages\rest_framework\renderers.py", line 100, in render
    ret = json.dumps(
  File "C:\Users\DigitalHouse\AppData\Local\Programs\Python\Python39\lib\site-packages\rest_framework\utils\json.py", line 25, in dumps
    return json.dumps(*args, **kwargs)
  File "C:\Users\DigitalHouse\AppData\Local\Programs\Python\Python39\lib\json\__init__.py", line 234, in dumps
    return cls(
  File "C:\Users\DigitalHouse\AppData\Local\Programs\Python\Python39\lib\json\encoder.py", line 199, in encode
    chunks = self.iterencode(o, _one_shot=True)
  File "C:\Users\DigitalHouse\AppData\Local\Programs\Python\Python39\lib\json\encoder.py", line 257, in iterencode
    return _iterencode(o, 0)
  File "C:\Users\DigitalHouse\AppData\Local\Programs\Python\Python39\lib\site-packages\rest_framework\utils\encoders.py", line 67, in default
    return super().default(obj)
  File "C:\Users\DigitalHouse\AppData\Local\Programs\Python\Python39\lib\json\encoder.py", line 179, in default
    raise TypeError(f'Object of type {o.__class__.__name__} '
TypeError: Object of type IntegerField is not JSON serializable
[03/Mar/2023 23:48:19] ERROR [django.server:161] "POST /property_owner/room_options/ HTTP/1.1" 500 109622
[03/Mar/2023 23:49:40] DEBUG [asyncio:623] Using proactor: IocpProactor
[03/Mar/2023 23:49:45] DEBUG [oauthlib.oauth2.rfc6749.endpoints.resource:70] Dispatching token_type Bearer request to <oauthlib.oauth2.rfc6749.tokens.BearerToken object at 0x0000016B54E89A40>.
[03/Mar/2023 23:49:46] ERROR [django.request:224] Internal Server Error: /property_owner/room_options/
Traceback (most recent call last):
  File "C:\Users\DigitalHouse\AppData\Local\Programs\Python\Python39\lib\site-packages\django\db\backends\utils.py", line 84, in _execute
    return self.cursor.execute(sql, params)
psycopg2.errors.UndefinedColumn: column "number_of_beds" of relation "property_owner_roomoptions" does not exist
LINE 1: ...y_id", "modified_by_id", "trash", "kind_of_beds", "number_of...
                                                             ^


The above exception was the direct cause of the following exception:

Traceback (most recent call last):
  File "C:\Users\DigitalHouse\AppData\Local\Programs\Python\Python39\lib\site-packages\django\core\handlers\exception.py", line 47, in inner
    response = get_response(request)
  File "C:\Users\DigitalHouse\AppData\Local\Programs\Python\Python39\lib\site-packages\django\core\handlers\base.py", line 181, in _get_response
    response = wrapped_callback(request, *callback_args, **callback_kwargs)
  File "C:\Users\DigitalHouse\AppData\Local\Programs\Python\Python39\lib\site-packages\django\views\decorators\csrf.py", line 54, in wrapped_view
    return view_func(*args, **kwargs)
  File "C:\Users\DigitalHouse\AppData\Local\Programs\Python\Python39\lib\site-packages\rest_framework\viewsets.py", line 125, in view
    return self.dispatch(request, *args, **kwargs)
  File "C:\Users\DigitalHouse\AppData\Local\Programs\Python\Python39\lib\site-packages\rest_framework\views.py", line 509, in dispatch
    response = self.handle_exception(exc)
  File "C:\Users\DigitalHouse\AppData\Local\Programs\Python\Python39\lib\site-packages\rest_framework\views.py", line 469, in handle_exception
    self.raise_uncaught_exception(exc)
  File "C:\Users\DigitalHouse\AppData\Local\Programs\Python\Python39\lib\site-packages\rest_framework\views.py", line 480, in raise_uncaught_exception
    raise exc
  File "C:\Users\DigitalHouse\AppData\Local\Programs\Python\Python39\lib\site-packages\rest_framework\views.py", line 506, in dispatch
    response = handler(request, *args, **kwargs)
  File "C:\Users\DigitalHouse\AppData\Local\Programs\Python\Python39\lib\site-packages\rest_framework\mixins.py", line 19, in create
    self.perform_create(serializer)
  File "C:\Users\DigitalHouse\AppData\Local\Programs\Python\Python39\lib\site-packages\rest_framework\mixins.py", line 24, in perform_create
    serializer.save()
  File "C:\Users\DigitalHouse\AppData\Local\Programs\Python\Python39\lib\site-packages\rest_framework\serializers.py", line 212, in save
    self.instance = self.create(validated_data)
  File "C:\Users\DigitalHouse\AppData\Local\Programs\Python\Python39\lib\site-packages\rest_framework\serializers.py", line 962, in create
    instance = ModelClass._default_manager.create(**validated_data)
  File "C:\Users\DigitalHouse\AppData\Local\Programs\Python\Python39\lib\site-packages\django\db\models\manager.py", line 85, in manager_method
    return getattr(self.get_queryset(), name)(*args, **kwargs)
  File "C:\Users\DigitalHouse\AppData\Local\Programs\Python\Python39\lib\site-packages\django\db\models\query.py", line 453, in create
    obj.save(force_insert=True, using=self.db)
  File "D:\Projects\Listing-Owner\property_owner\models.py", line 84, in save
    super(RoomOptions, self).save(*args, **kwargs)
  File "C:\Users\DigitalHouse\AppData\Local\Programs\Python\Python39\lib\site-packages\django\db\models\base.py", line 726, in save
    self.save_base(using=using, force_insert=force_insert,
  File "C:\Users\DigitalHouse\AppData\Local\Programs\Python\Python39\lib\site-packages\django\db\models\base.py", line 763, in save_base
    updated = self._save_table(
  File "C:\Users\DigitalHouse\AppData\Local\Programs\Python\Python39\lib\site-packages\django\db\models\base.py", line 868, in _save_table
    results = self._do_insert(cls._base_manager, using, fields, returning_fields, raw)
  File "C:\Users\DigitalHouse\AppData\Local\Programs\Python\Python39\lib\site-packages\django\db\models\base.py", line 906, in _do_insert
    return manager._insert(
  File "C:\Users\DigitalHouse\AppData\Local\Programs\Python\Python39\lib\site-packages\django\db\models\manager.py", line 85, in manager_method
    return getattr(self.get_queryset(), name)(*args, **kwargs)
  File "C:\Users\DigitalHouse\AppData\Local\Programs\Python\Python39\lib\site-packages\django\db\models\query.py", line 1270, in _insert
    return query.get_compiler(using=using).execute_sql(returning_fields)
  File "C:\Users\DigitalHouse\AppData\Local\Programs\Python\Python39\lib\site-packages\django\db\models\sql\compiler.py", line 1416, in execute_sql
    cursor.execute(sql, params)
  File "C:\Users\DigitalHouse\AppData\Local\Programs\Python\Python39\lib\site-packages\django\db\backends\utils.py", line 98, in execute
    return super().execute(sql, params)
  File "C:\Users\DigitalHouse\AppData\Local\Programs\Python\Python39\lib\site-packages\django\db\backends\utils.py", line 66, in execute
    return self._execute_with_wrappers(sql, params, many=False, executor=self._execute)
  File "C:\Users\DigitalHouse\AppData\Local\Programs\Python\Python39\lib\site-packages\django\db\backends\utils.py", line 75, in _execute_with_wrappers
    return executor(sql, params, many, context)
  File "C:\Users\DigitalHouse\AppData\Local\Programs\Python\Python39\lib\site-packages\django\db\backends\utils.py", line 84, in _execute
    return self.cursor.execute(sql, params)
  File "C:\Users\DigitalHouse\AppData\Local\Programs\Python\Python39\lib\site-packages\django\db\utils.py", line 90, in __exit__
    raise dj_exc_value.with_traceback(traceback) from exc_value
  File "C:\Users\DigitalHouse\AppData\Local\Programs\Python\Python39\lib\site-packages\django\db\backends\utils.py", line 84, in _execute
    return self.cursor.execute(sql, params)
django.db.utils.ProgrammingError: column "number_of_beds" of relation "property_owner_roomoptions" does not exist
LINE 1: ...y_id", "modified_by_id", "trash", "kind_of_beds", "number_of...
                                                             ^

[03/Mar/2023 23:49:46] ERROR [django.server:161] "POST /property_owner/room_options/ HTTP/1.1" 500 211682
[03/Mar/2023 23:50:03] DEBUG [asyncio:623] Using proactor: IocpProactor
[03/Mar/2023 23:50:03] DEBUG [asyncio:623] Using proactor: IocpProactor
